Warning: no access to tty (Bad file descriptor).
Thus no job control in this shell.
Mon Sep  5 11:20:25 GMT 2022
jlab.py:30: SyntaxWarning: "is not" with a literal. Did you mean "!="?
  elif dashinfo is not '0':
jlab.py:33: SyntaxWarning: "is not" with a literal. Did you mean "!="?
  if dashinfo is not '0':
Fail to get yarn configuration. {"type":"error","data":"An unexpected error occurred: \"ENOENT: no such file or directory, open '/home1/.yarnrc'\"."}
{"type":"info","data":"If you think this is a bug, please open a bug report with the information provided in \"/home1/datahome/mdemol/.miniconda3/envs/m2env/lib/python3.8/site-packages/jupyterlab/yarn-error.log\"."}
{"type":"info","data":"Visit https://yarnpkg.com/en/docs/cli/config for documentation about this command."}

[I 2022-09-05 11:20:49.575 ServerApp] jupyterlab | extension was successfully linked.
[W 2022-09-05 11:20:49.584 NotebookApp] 'password' has moved from NotebookApp to ServerApp. This config will be passed to ServerApp. Be sure to update your config before our next release.
[I 2022-09-05 11:20:49.592 ServerApp] nbclassic | extension was successfully linked.
[I 2022-09-05 11:20:54.427 ServerApp] notebook_shim | extension was successfully linked.
[I 2022-09-05 11:20:55.065 ServerApp] notebook_shim | extension was successfully loaded.
[I 2022-09-05 11:20:55.066 LabApp] JupyterLab extension loaded from /home1/datahome/mdemol/.miniconda3/envs/m2env/lib/python3.8/site-packages/jupyterlab
[I 2022-09-05 11:20:55.066 LabApp] JupyterLab application directory is /home1/datahome/mdemol/.miniconda3/envs/m2env/share/jupyter/lab
[I 2022-09-05 11:20:55.070 ServerApp] jupyterlab | extension was successfully loaded.
[I 2022-09-05 11:20:55.195 ServerApp] nbclassic | extension was successfully loaded.
[I 2022-09-05 11:20:55.195 ServerApp] Serving notebooks from local directory: /home1/datahome/mdemol
[I 2022-09-05 11:20:55.195 ServerApp] Jupyter Server 1.16.0 is running at:
[I 2022-09-05 11:20:55.195 ServerApp] http://r1i3n34:8877/lab
[I 2022-09-05 11:20:55.195 ServerApp]  or http://127.0.0.1:8877/lab
[I 2022-09-05 11:20:55.195 ServerApp] Use Control-C to stop this server and shut down all kernels (twice to skip confirmation).
[I 2022-09-05 11:22:39.716 LabApp] Build is up to date
[I 2022-09-05 11:22:44.904 ServerApp] Kernel started: 6567d391-a4e4-412a-9cd1-f4d3d3a48049
[I 2022-09-05 11:22:44.905 ServerApp] Kernel started: d44879a7-db14-4101-8bf9-aa753e6354fc
[I 2022-09-05 11:22:44.906 ServerApp] Kernel started: cdfcdd83-4ca6-4ce7-abe7-da082dbfbb59
[E 2022-09-05 11:23:02.660 ServerApp] Kernel info request failed, assuming current {}
[W 2022-09-05 11:23:07.172 ServerApp] Nudge: attempt 10 on kernel d44879a7-db14-4101-8bf9-aa753e6354fc
[W 2022-09-05 11:23:12.183 ServerApp] Nudge: attempt 20 on kernel d44879a7-db14-4101-8bf9-aa753e6354fc
Traceback (most recent call last):
  File "/home1/datahome/mdemol/.miniconda3/envs/m2env/lib/python3.8/runpy.py", line 194, in _run_module_as_main
    return _run_code(code, main_globals, None,
  File "/home1/datahome/mdemol/.miniconda3/envs/m2env/lib/python3.8/runpy.py", line 87, in _run_code
    exec(code, run_globals)
  File "/home1/datahome/mdemol/.miniconda3/envs/m2env/lib/python3.8/site-packages/ipykernel_launcher.py", line 17, in <module>
    app.launch_new_instance()
  File "/home1/datahome/mdemol/.miniconda3/envs/m2env/lib/python3.8/site-packages/traitlets/config/application.py", line 845, in launch_instance
    app.initialize(argv)
  File "/home1/datahome/mdemol/.miniconda3/envs/m2env/lib/python3.8/site-packages/traitlets/config/application.py", line 88, in inner
    return method(app, *args, **kwargs)
  File "/home1/datahome/mdemol/.miniconda3/envs/m2env/lib/python3.8/site-packages/ipykernel/kernelapp.py", line 661, in initialize
    self.init_sockets()
  File "/home1/datahome/mdemol/.miniconda3/envs/m2env/lib/python3.8/site-packages/ipykernel/kernelapp.py", line 307, in init_sockets
    self.shell_port = self._bind_socket(self.shell_socket, self.shell_port)
  File "/home1/datahome/mdemol/.miniconda3/envs/m2env/lib/python3.8/site-packages/ipykernel/kernelapp.py", line 244, in _bind_socket
    return self._try_bind_socket(s, port)
  File "/home1/datahome/mdemol/.miniconda3/envs/m2env/lib/python3.8/site-packages/ipykernel/kernelapp.py", line 220, in _try_bind_socket
    s.bind("tcp://%s:%i" % (self.ip, port))
  File "/home1/datahome/mdemol/.miniconda3/envs/m2env/lib/python3.8/site-packages/zmq/sugar/socket.py", line 214, in bind
    super().bind(addr)
  File "zmq/backend/cython/socket.pyx", line 540, in zmq.backend.cython.socket.Socket.bind
  File "zmq/backend/cython/checkrc.pxd", line 28, in zmq.backend.cython.checkrc._check_rc
zmq.error.ZMQError: Address already in use
readline: readline: /etc/inputrc: line 19: term: unknown variable name
/etc/inputrc: line 19: term: unknown variable name
[W 2022-09-05 11:23:17.192 ServerApp] Nudge: attempt 30 on kernel d44879a7-db14-4101-8bf9-aa753e6354fc
[IPKernelApp] ERROR | No such comm target registered: jupyter.widget.control
[IPKernelApp] WARNING | No such comm: 77c9cb96-014e-4ca5-a4fd-735501fa29ae
[IPKernelApp] ERROR | No such comm target registered: jupyter.widget.control
[IPKernelApp] WARNING | No such comm: ec5f4e1b-6473-4703-9f2d-39eeb919a41d
[I 2022-09-05 11:23:17.636 ServerApp] AsyncIOLoopKernelRestarter: restarting kernel (1/5), keep random ports
[W 2022-09-05 11:23:17.636 ServerApp] kernel d44879a7-db14-4101-8bf9-aa753e6354fc restarted
Traceback (most recent call last):
  File "/home1/datahome/mdemol/.miniconda3/envs/m2env/lib/python3.8/runpy.py", line 194, in _run_module_as_main
    return _run_code(code, main_globals, None,
  File "/home1/datahome/mdemol/.miniconda3/envs/m2env/lib/python3.8/runpy.py", line 87, in _run_code
    exec(code, run_globals)
  File "/home1/datahome/mdemol/.miniconda3/envs/m2env/lib/python3.8/site-packages/ipykernel_launcher.py", line 17, in <module>
    app.launch_new_instance()
  File "/home1/datahome/mdemol/.miniconda3/envs/m2env/lib/python3.8/site-packages/traitlets/config/application.py", line 845, in launch_instance
    app.initialize(argv)
  File "/home1/datahome/mdemol/.miniconda3/envs/m2env/lib/python3.8/site-packages/traitlets/config/application.py", line 88, in inner
    return method(app, *args, **kwargs)
  File "/home1/datahome/mdemol/.miniconda3/envs/m2env/lib/python3.8/site-packages/ipykernel/kernelapp.py", line 661, in initialize
    self.init_sockets()
  File "/home1/datahome/mdemol/.miniconda3/envs/m2env/lib/python3.8/site-packages/ipykernel/kernelapp.py", line 307, in init_sockets
    self.shell_port = self._bind_socket(self.shell_socket, self.shell_port)
  File "/home1/datahome/mdemol/.miniconda3/envs/m2env/lib/python3.8/site-packages/ipykernel/kernelapp.py", line 244, in _bind_socket
    return self._try_bind_socket(s, port)
  File "/home1/datahome/mdemol/.miniconda3/envs/m2env/lib/python3.8/site-packages/ipykernel/kernelapp.py", line 220, in _try_bind_socket
    s.bind("tcp://%s:%i" % (self.ip, port))
  File "/home1/datahome/mdemol/.miniconda3/envs/m2env/lib/python3.8/site-packages/zmq/sugar/socket.py", line 214, in bind
    super().bind(addr)
  File "zmq/backend/cython/socket.pyx", line 540, in zmq.backend.cython.socket.Socket.bind
  File "zmq/backend/cython/checkrc.pxd", line 28, in zmq.backend.cython.checkrc._check_rc
zmq.error.ZMQError: Address already in use
[W 2022-09-05 11:23:19.287 ServerApp] Replacing stale connection: d44879a7-db14-4101-8bf9-aa753e6354fc:270b38f6-1587-476c-95db-6675c858c1eb
[I 2022-09-05 11:23:19.700 ServerApp] Starting buffering for d44879a7-db14-4101-8bf9-aa753e6354fc:270b38f6-1587-476c-95db-6675c858c1eb
[I 2022-09-05 11:23:19.701 ServerApp] Restoring connection for d44879a7-db14-4101-8bf9-aa753e6354fc:270b38f6-1587-476c-95db-6675c858c1eb
[I 2022-09-05 11:23:20.655 ServerApp] AsyncIOLoopKernelRestarter: restarting kernel (2/5), keep random ports
[W 2022-09-05 11:23:20.655 ServerApp] kernel d44879a7-db14-4101-8bf9-aa753e6354fc restarted
[W 2022-09-05 11:23:20.676 ServerApp] Replacing stale connection: d44879a7-db14-4101-8bf9-aa753e6354fc:270b38f6-1587-476c-95db-6675c858c1eb
[I 2022-09-05 11:23:20.705 ServerApp] Starting buffering for d44879a7-db14-4101-8bf9-aa753e6354fc:270b38f6-1587-476c-95db-6675c858c1eb
[I 2022-09-05 11:23:20.705 ServerApp] Restoring connection for d44879a7-db14-4101-8bf9-aa753e6354fc:270b38f6-1587-476c-95db-6675c858c1eb
Traceback (most recent call last):
  File "/home1/datahome/mdemol/.miniconda3/envs/m2env/lib/python3.8/runpy.py", line 194, in _run_module_as_main
    return _run_code(code, main_globals, None,
  File "/home1/datahome/mdemol/.miniconda3/envs/m2env/lib/python3.8/runpy.py", line 87, in _run_code
    exec(code, run_globals)
  File "/home1/datahome/mdemol/.miniconda3/envs/m2env/lib/python3.8/site-packages/ipykernel_launcher.py", line 17, in <module>
    app.launch_new_instance()
  File "/home1/datahome/mdemol/.miniconda3/envs/m2env/lib/python3.8/site-packages/traitlets/config/application.py", line 845, in launch_instance
    app.initialize(argv)
  File "/home1/datahome/mdemol/.miniconda3/envs/m2env/lib/python3.8/site-packages/traitlets/config/application.py", line 88, in inner
    return method(app, *args, **kwargs)
  File "/home1/datahome/mdemol/.miniconda3/envs/m2env/lib/python3.8/site-packages/ipykernel/kernelapp.py", line 661, in initialize
    self.init_sockets()
  File "/home1/datahome/mdemol/.miniconda3/envs/m2env/lib/python3.8/site-packages/ipykernel/kernelapp.py", line 307, in init_sockets
    self.shell_port = self._bind_socket(self.shell_socket, self.shell_port)
  File "/home1/datahome/mdemol/.miniconda3/envs/m2env/lib/python3.8/site-packages/ipykernel/kernelapp.py", line 244, in _bind_socket
    return self._try_bind_socket(s, port)
  File "/home1/datahome/mdemol/.miniconda3/envs/m2env/lib/python3.8/site-packages/ipykernel/kernelapp.py", line 220, in _try_bind_socket
    s.bind("tcp://%s:%i" % (self.ip, port))
  File "/home1/datahome/mdemol/.miniconda3/envs/m2env/lib/python3.8/site-packages/zmq/sugar/socket.py", line 214, in bind
    super().bind(addr)
  File "zmq/backend/cython/socket.pyx", line 540, in zmq.backend.cython.socket.Socket.bind
  File "zmq/backend/cython/checkrc.pxd", line 28, in zmq.backend.cython.checkrc._check_rc
zmq.error.ZMQError: Address already in use
[I 2022-09-05 11:23:23.674 ServerApp] AsyncIOLoopKernelRestarter: restarting kernel (3/5), keep random ports
[W 2022-09-05 11:23:23.674 ServerApp] kernel d44879a7-db14-4101-8bf9-aa753e6354fc restarted
Traceback (most recent call last):
  File "/home1/datahome/mdemol/.miniconda3/envs/m2env/lib/python3.8/runpy.py", line 194, in _run_module_as_main
    return _run_code(code, main_globals, None,
  File "/home1/datahome/mdemol/.miniconda3/envs/m2env/lib/python3.8/runpy.py", line 87, in _run_code
    exec(code, run_globals)
  File "/home1/datahome/mdemol/.miniconda3/envs/m2env/lib/python3.8/site-packages/ipykernel_launcher.py", line 17, in <module>
    app.launch_new_instance()
  File "/home1/datahome/mdemol/.miniconda3/envs/m2env/lib/python3.8/site-packages/traitlets/config/application.py", line 845, in launch_instance
    app.initialize(argv)
  File "/home1/datahome/mdemol/.miniconda3/envs/m2env/lib/python3.8/site-packages/traitlets/config/application.py", line 88, in inner
    return method(app, *args, **kwargs)
  File "/home1/datahome/mdemol/.miniconda3/envs/m2env/lib/python3.8/site-packages/ipykernel/kernelapp.py", line 661, in initialize
    self.init_sockets()
  File "/home1/datahome/mdemol/.miniconda3/envs/m2env/lib/python3.8/site-packages/ipykernel/kernelapp.py", line 307, in init_sockets
    self.shell_port = self._bind_socket(self.shell_socket, self.shell_port)
  File "/home1/datahome/mdemol/.miniconda3/envs/m2env/lib/python3.8/site-packages/ipykernel/kernelapp.py", line 244, in _bind_socket
    return self._try_bind_socket(s, port)
  File "/home1/datahome/mdemol/.miniconda3/envs/m2env/lib/python3.8/site-packages/ipykernel/kernelapp.py", line 220, in _try_bind_socket
    s.bind("tcp://%s:%i" % (self.ip, port))
  File "/home1/datahome/mdemol/.miniconda3/envs/m2env/lib/python3.8/site-packages/zmq/sugar/socket.py", line 214, in bind
    super().bind(addr)
  File "zmq/backend/cython/socket.pyx", line 540, in zmq.backend.cython.socket.Socket.bind
  File "zmq/backend/cython/checkrc.pxd", line 28, in zmq.backend.cython.checkrc._check_rc
zmq.error.ZMQError: Address already in use
[W 2022-09-05 11:23:24.854 ServerApp] Replacing stale connection: d44879a7-db14-4101-8bf9-aa753e6354fc:270b38f6-1587-476c-95db-6675c858c1eb
[I 2022-09-05 11:23:25.217 ServerApp] Starting buffering for d44879a7-db14-4101-8bf9-aa753e6354fc:270b38f6-1587-476c-95db-6675c858c1eb
[I 2022-09-05 11:23:25.218 ServerApp] Restoring connection for d44879a7-db14-4101-8bf9-aa753e6354fc:270b38f6-1587-476c-95db-6675c858c1eb
[I 2022-09-05 11:23:26.693 ServerApp] AsyncIOLoopKernelRestarter: restarting kernel (4/5), keep random ports
[W 2022-09-05 11:23:26.693 ServerApp] kernel d44879a7-db14-4101-8bf9-aa753e6354fc restarted
[W 2022-09-05 11:23:27.111 ServerApp] Replacing stale connection: d44879a7-db14-4101-8bf9-aa753e6354fc:270b38f6-1587-476c-95db-6675c858c1eb
[I 2022-09-05 11:23:27.223 ServerApp] Starting buffering for d44879a7-db14-4101-8bf9-aa753e6354fc:270b38f6-1587-476c-95db-6675c858c1eb
[I 2022-09-05 11:23:27.224 ServerApp] Restoring connection for d44879a7-db14-4101-8bf9-aa753e6354fc:270b38f6-1587-476c-95db-6675c858c1eb
Traceback (most recent call last):
  File "/home1/datahome/mdemol/.miniconda3/envs/m2env/lib/python3.8/runpy.py", line 194, in _run_module_as_main
    return _run_code(code, main_globals, None,
  File "/home1/datahome/mdemol/.miniconda3/envs/m2env/lib/python3.8/runpy.py", line 87, in _run_code
    exec(code, run_globals)
  File "/home1/datahome/mdemol/.miniconda3/envs/m2env/lib/python3.8/site-packages/ipykernel_launcher.py", line 17, in <module>
    app.launch_new_instance()
  File "/home1/datahome/mdemol/.miniconda3/envs/m2env/lib/python3.8/site-packages/traitlets/config/application.py", line 845, in launch_instance
    app.initialize(argv)
  File "/home1/datahome/mdemol/.miniconda3/envs/m2env/lib/python3.8/site-packages/traitlets/config/application.py", line 88, in inner
    return method(app, *args, **kwargs)
  File "/home1/datahome/mdemol/.miniconda3/envs/m2env/lib/python3.8/site-packages/ipykernel/kernelapp.py", line 661, in initialize
    self.init_sockets()
  File "/home1/datahome/mdemol/.miniconda3/envs/m2env/lib/python3.8/site-packages/ipykernel/kernelapp.py", line 307, in init_sockets
    self.shell_port = self._bind_socket(self.shell_socket, self.shell_port)
  File "/home1/datahome/mdemol/.miniconda3/envs/m2env/lib/python3.8/site-packages/ipykernel/kernelapp.py", line 244, in _bind_socket
    return self._try_bind_socket(s, port)
  File "/home1/datahome/mdemol/.miniconda3/envs/m2env/lib/python3.8/site-packages/ipykernel/kernelapp.py", line 220, in _try_bind_socket
    s.bind("tcp://%s:%i" % (self.ip, port))
  File "/home1/datahome/mdemol/.miniconda3/envs/m2env/lib/python3.8/site-packages/zmq/sugar/socket.py", line 214, in bind
    super().bind(addr)
  File "zmq/backend/cython/socket.pyx", line 540, in zmq.backend.cython.socket.Socket.bind
  File "zmq/backend/cython/checkrc.pxd", line 28, in zmq.backend.cython.checkrc._check_rc
zmq.error.ZMQError: Address already in use
[I 2022-09-05 11:23:29.711 ServerApp] AsyncIOLoopKernelRestarter: restarting kernel (5/5), keep random ports
[W 2022-09-05 11:23:29.712 ServerApp] kernel d44879a7-db14-4101-8bf9-aa753e6354fc restarted
[W 2022-09-05 11:23:29.722 ServerApp] Replacing stale connection: d44879a7-db14-4101-8bf9-aa753e6354fc:270b38f6-1587-476c-95db-6675c858c1eb
[I 2022-09-05 11:23:29.731 ServerApp] Starting buffering for d44879a7-db14-4101-8bf9-aa753e6354fc:270b38f6-1587-476c-95db-6675c858c1eb
[I 2022-09-05 11:23:29.742 ServerApp] Restoring connection for d44879a7-db14-4101-8bf9-aa753e6354fc:270b38f6-1587-476c-95db-6675c858c1eb
Traceback (most recent call last):
  File "/home1/datahome/mdemol/.miniconda3/envs/m2env/lib/python3.8/runpy.py", line 194, in _run_module_as_main
    return _run_code(code, main_globals, None,
  File "/home1/datahome/mdemol/.miniconda3/envs/m2env/lib/python3.8/runpy.py", line 87, in _run_code
    exec(code, run_globals)
  File "/home1/datahome/mdemol/.miniconda3/envs/m2env/lib/python3.8/site-packages/ipykernel_launcher.py", line 17, in <module>
    app.launch_new_instance()
  File "/home1/datahome/mdemol/.miniconda3/envs/m2env/lib/python3.8/site-packages/traitlets/config/application.py", line 845, in launch_instance
    app.initialize(argv)
  File "/home1/datahome/mdemol/.miniconda3/envs/m2env/lib/python3.8/site-packages/traitlets/config/application.py", line 88, in inner
    return method(app, *args, **kwargs)
  File "/home1/datahome/mdemol/.miniconda3/envs/m2env/lib/python3.8/site-packages/ipykernel/kernelapp.py", line 661, in initialize
    self.init_sockets()
  File "/home1/datahome/mdemol/.miniconda3/envs/m2env/lib/python3.8/site-packages/ipykernel/kernelapp.py", line 307, in init_sockets
    self.shell_port = self._bind_socket(self.shell_socket, self.shell_port)
  File "/home1/datahome/mdemol/.miniconda3/envs/m2env/lib/python3.8/site-packages/ipykernel/kernelapp.py", line 244, in _bind_socket
    return self._try_bind_socket(s, port)
  File "/home1/datahome/mdemol/.miniconda3/envs/m2env/lib/python3.8/site-packages/ipykernel/kernelapp.py", line 220, in _try_bind_socket
    s.bind("tcp://%s:%i" % (self.ip, port))
  File "/home1/datahome/mdemol/.miniconda3/envs/m2env/lib/python3.8/site-packages/zmq/sugar/socket.py", line 214, in bind
    super().bind(addr)
  File "zmq/backend/cython/socket.pyx", line 540, in zmq.backend.cython.socket.Socket.bind
  File "zmq/backend/cython/checkrc.pxd", line 28, in zmq.backend.cython.checkrc._check_rc
zmq.error.ZMQError: Address already in use
[W 2022-09-05 11:23:32.731 ServerApp] AsyncIOLoopKernelRestarter: restart failed
[W 2022-09-05 11:23:32.731 ServerApp] Kernel d44879a7-db14-4101-8bf9-aa753e6354fc died, removing from map.
[E 2022-09-05 11:23:32.731 ServerApp] kernel d44879a7-db14-4101-8bf9-aa753e6354fc restarted failed!
[I 2022-09-05 11:29:38.632 ServerApp] Kernel restarted: 6567d391-a4e4-412a-9cd1-f4d3d3a48049
[I 2022-09-05 11:29:38.635 ServerApp] Starting buffering for 6567d391-a4e4-412a-9cd1-f4d3d3a48049:45e9fa0a-5a71-4190-8716-2b71350a321f
[I 2022-09-05 11:29:38.641 ServerApp] Restoring connection for 6567d391-a4e4-412a-9cd1-f4d3d3a48049:45e9fa0a-5a71-4190-8716-2b71350a321f
readline: /etc/inputrc: line 19: term: unknown variable name
[IPKernelApp] ERROR | No such comm target registered: jupyter.widget.control
[IPKernelApp] WARNING | No such comm: 12232627-8a81-48e0-a248-0583f8aa7ad9
[I 2022-09-05 11:30:43.344 ServerApp] Saving file at /m2_2022/sandbox/statistic_bars_example.ipynb
[I 2022-09-05 11:32:44.268 ServerApp] Saving file at /m2_2022/sandbox/statistic_bars_example.ipynb
[I 2022-09-05 11:36:44.401 ServerApp] Saving file at /m2_2022/sandbox/statistic_bars_example.ipynb
[I 2022-09-05 11:38:44.513 ServerApp] Saving file at /m2_2022/sandbox/statistic_bars_example.ipynb
[I 2022-09-05 11:40:44.278 ServerApp] Saving file at /m2_2022/sandbox/diag_closure_bars.ipynb
[I 2022-09-05 11:40:44.690 ServerApp] Saving file at /m2_2022/sandbox/statistic_bars_example.ipynb
[I 2022-09-05 11:42:44.740 ServerApp] Saving file at /m2_2022/sandbox/diag_closure_bars.ipynb
[I 2022-09-05 11:43:58.986 ServerApp] Kernel restarted: cdfcdd83-4ca6-4ce7-abe7-da082dbfbb59
readline: /etc/inputrc: line 19: term: unknown variable name
[IPKernelApp] ERROR | No such comm target registered: jupyter.widget.control
[IPKernelApp] WARNING | No such comm: f98db73d-6072-4bd6-9970-9cb47445c88f
[I 2022-09-05 11:44:44.811 ServerApp] Saving file at /m2_2022/sandbox/statistic_bars_example.ipynb
[I 2022-09-05 11:44:45.237 ServerApp] Saving file at /m2_2022/sandbox/diag_closure_bars.ipynb
[I 2022-09-05 11:46:45.614 ServerApp] Saving file at /m2_2022/sandbox/diag_closure_bars.ipynb
[I 2022-09-05 12:59:25.392 ServerApp] Kernel started: db339d60-7773-46db-a042-5d540a9afea5
readline: /etc/inputrc: line 19: term: unknown variable name
[IPKernelApp] ERROR | No such comm target registered: jupyter.widget.control
[IPKernelApp] WARNING | No such comm: 408d60f4-a5dd-412d-95c6-4a2c7dd839b2
[I 2022-09-05 12:59:33.062 ServerApp] Saving file at /m2_2022/sandbox/diag_closure_bars.ipynb
[I 2022-09-05 13:00:06.715 ServerApp] Kernel started: d0a44eee-4d1c-4684-aae3-68be51a0e62e
readline: /etc/inputrc: line 19: term: unknown variable name
[IPKernelApp] ERROR | No such comm target registered: jupyter.widget.control
[IPKernelApp] WARNING | No such comm: 9b81c55b-b11d-406a-b982-fe641c7c10e2
[I 2022-09-05 13:00:13.290 ServerApp] Kernel started: 733a0e22-d1d6-4d27-9a23-10f34ede992e
readline: /etc/inputrc: line 19: term: unknown variable name
[IPKernelApp] ERROR | No such comm target registered: jupyter.widget.control
[IPKernelApp] WARNING | No such comm: 9b5ba900-a05b-4498-a828-a49af0d9e6af
[I 2022-09-05 13:00:26.426 ServerApp] Kernel started: 468080a9-3e5f-41b2-97d3-354944af9333
readline: /etc/inputrc: line 19: term: unknown variable name
[IPKernelApp] ERROR | No such comm target registered: jupyter.widget.control
[IPKernelApp] WARNING | No such comm: 597c9282-632c-4bd0-acfb-d479b7b6b1b6
[I 2022-09-05 13:02:24.691 ServerApp] Saving file at /m2_2022/sandbox/animation.ipynb
[I 2022-09-05 13:04:24.961 ServerApp] Saving file at /m2_2022/sandbox/animation.ipynb
distributed.diskutils - INFO - Found stale lock file and directory '/home1/datahome/mdemol/m2_2022/sandbox/dask-worker-space/worker-874d9_vo', purging
distributed.diskutils - INFO - Found stale lock file and directory '/home1/datahome/mdemol/m2_2022/sandbox/dask-worker-space/worker-x0jskwon', purging
distributed.diskutils - INFO - Found stale lock file and directory '/home1/datahome/mdemol/m2_2022/sandbox/dask-worker-space/worker-dv9x69x8', purging
distributed.diskutils - INFO - Found stale lock file and directory '/home1/datahome/mdemol/m2_2022/sandbox/dask-worker-space/worker-p652jo1i', purging
distributed.diskutils - INFO - Found stale lock file and directory '/home1/datahome/mdemol/m2_2022/sandbox/dask-worker-space/worker-a0p4bqhm', purging
[I 2022-09-05 13:06:25.276 ServerApp] Saving file at /m2_2022/sandbox/animation.ipynb
[I 2022-09-05 13:08:25.842 ServerApp] Saving file at /m2_2022/sandbox/animation.ipynb
[I 2022-09-05 13:10:26.063 ServerApp] Saving file at /m2_2022/sandbox/animation.ipynb
/home1/datahome/mdemol/.miniconda3/envs/m2env/lib/python3.8/contextlib.py:120: UserWarning: Creating scratch directories is taking a surprisingly long time. This is often due to running workers on a network file system. Consider specifying a local-directory to point workers to write scratch data to a local disk.
  next(self.gen)
/home1/datahome/mdemol/.miniconda3/envs/m2env/lib/python3.8/contextlib.py:120: UserWarning: Creating scratch directories is taking a surprisingly long time. This is often due to running workers on a network file system. Consider specifying a local-directory to point workers to write scratch data to a local disk.
  next(self.gen)
/home1/datahome/mdemol/.miniconda3/envs/m2env/lib/python3.8/contextlib.py:120: UserWarning: Creating scratch directories is taking a surprisingly long time. This is often due to running workers on a network file system. Consider specifying a local-directory to point workers to write scratch data to a local disk.
  next(self.gen)
/home1/datahome/mdemol/.miniconda3/envs/m2env/lib/python3.8/contextlib.py:120: UserWarning: Creating scratch directories is taking a surprisingly long time. This is often due to running workers on a network file system. Consider specifying a local-directory to point workers to write scratch data to a local disk.
  next(self.gen)
[I 2022-09-05 14:40:06.042 ServerApp] Saving file at /m2_2022/sandbox/statistic_bars_example.ipynb
[I 2022-09-05 14:40:06.141 ServerApp] Saving file at /m2_2022/sandbox/animation.ipynb
[I 2022-09-05 14:43:51.194 ServerApp] Starting buffering for 468080a9-3e5f-41b2-97d3-354944af9333:a7fc48cc-91a7-4907-9d78-4b18dcac0db1
[I 2022-09-05 14:43:52.710 ServerApp] Starting buffering for d0a44eee-4d1c-4684-aae3-68be51a0e62e:ded6e92c-d9b6-4810-8bda-c2b0844d4494
[I 2022-09-05 14:43:53.873 ServerApp] Starting buffering for db339d60-7773-46db-a042-5d540a9afea5:91715e4b-77a2-48dd-8635-7c6d25ebdf03
[I 2022-09-05 14:44:06.158 ServerApp] Saving file at /m2_2022/sandbox/statistic_bars_example.ipynb
[I 2022-09-05 14:46:06.280 ServerApp] Saving file at /m2_2022/sandbox/statistic_bars_example.ipynb
[I 2022-09-05 15:02:13.293 ServerApp] Saving file at /m2_2022/sandbox/statistic_bars_example.ipynb
[I 2022-09-05 15:04:13.628 ServerApp] Saving file at /m2_2022/sandbox/statistic_bars_example.ipynb
Terminated
[C 2022-09-05 15:44:11.413 ServerApp] received signal 15, stopping
[I 2022-09-05 15:44:11.466 ServerApp] Shutting down 3 extensions
[I 2022-09-05 15:44:11.466 ServerApp] Shutting down 6 kernels
[I 2022-09-05 15:44:11.467 ServerApp] Kernel shutdown: 468080a9-3e5f-41b2-97d3-354944af9333
[I 2022-09-05 15:44:11.467 ServerApp] Kernel shutdown: d0a44eee-4d1c-4684-aae3-68be51a0e62e
[I 2022-09-05 15:44:11.467 ServerApp] Kernel shutdown: 6567d391-a4e4-412a-9cd1-f4d3d3a48049
[I 2022-09-05 15:44:11.467 ServerApp] Kernel shutdown: 733a0e22-d1d6-4d27-9a23-10f34ede992e
[I 2022-09-05 15:44:11.468 ServerApp] Kernel shutdown: db339d60-7773-46db-a042-5d540a9afea5
[I 2022-09-05 15:44:11.468 ServerApp] Kernel shutdown: cdfcdd83-4ca6-4ce7-abe7-da082dbfbb59
/home1/datahome/mdemol/.miniconda3/envs/m2env/lib/python3.8/contextlib.py:120: UserWarning: Creating scratch directories is taking a surprisingly long time. This is often due to running workers on a network file system. Consider specifying a local-directory to point workers to write scratch data to a local disk.
  next(self.gen)
[I 2022-09-05 15:44:14.090 ServerApp] Shutting down 0 terminals
